Workbook

Sheet Current Roster
A6: Brawl | D6: Melee | G6: Ultimate
A7: Bowser | D7: Bayonetta | G7: Captain Falcon
A8: Bowser Jr. | D8: Cloud | G8: Chrom
A9: Corrin | D9: Daisy | G9: Dr. Mario
A10: Dark Samus | D10: Dark Pit | G10: Fox
A11: Diddy Kong | D11: DK | G11: Ice Climbers
A12: Erdrick | D12: Duck Hunt | G12: Ike
A13: Falco | D13: Ganondorf | G13: Inkling
A14: Jigglypuff | D14: Greninja | G14: Joker
A15: Ken | D15: Incineroar | G15: King Dedede
A16: Kirby | D16: Isabelle | G16: Little Mac
A17: Luigi | D17: King K. Rool | G17: Lucario
... A30: Wario | D30: Zelda | G30: Wii Fit Trainer
A31: Young Link

Sheet Ultimate Draft
A1: ULTIMATE DRAFT
A6: Champions | B6: Diddy Kong | D6: Pit
B7: Kirby | D7: Wario
B8: Marth | D8: Olimar
A9: Round 1: | B9: Toon Link | D9: Luigi | F9: Pikachu
F10: Mario
A11: Round 2: | B11: Sonic | D11: Link | F11: Mewtwo
F12: Samus
A13: Round 3: | B13: ROB | D13: Ike | F13: Falco
B14: Ridley | D14: DK | F14: Mr. Game & Watch
A15: Round 4: | B15: Ryu | D15: Meta Knight | F15: Bowser
B16: Wolf | D16: Cloud | F16: Yoshi
A17: Round 5: | B17: Young Link | D17: Ganondorf | F17: Captain Falcon
B18: Simon Belmont | D18: Fox | F18: Mega Man
A19: Round 6: | B19: Bayonetta | D19: Zelda | F19: Ness
B20: Roy | D20: Pac-Man | F20: Shulk
A21: Round 7: | B21: Corrin | D21: Lucario | F21: Lucas
B22: Little Mac | D22: Inkling | F22: Greninja
A23: Round 8: | B23: Richter Blemont | D23: Palutena | F23: Snake
B24: Robin | D24: King K. Rool | F24: Chrom
A25: Round 9: | B25: Dr. Mario | D25: Lucina | F25: Pichu
B26: Pokemon Trainer | D26: Duck Hunt | F26: King Dedede
A27: Round 10: | B27: Bowser Jr. | D27: Ice Climbers | F27: Peach
B28: Rosalina & Luma | D28: Isabelle | F28: Daisy
A29: Round 11: | B29: Wii Fit Trainer | D29: Villager | F29: Jigglypuff
A30: Round 12: | B30: Ken | D30: Dark Pit | F30: Incineroar
B31: Dark Samus | F31: Sheik

Sheet Championship History
F3: Unified Tag Team: | G3: Ridley + Dark Samus
B7: Brawl Champion: | C7: Toon Link | H7: Melee Champion: | I7: Lucas | N7: Ultimate Champion: | P7: Erdrick
B8: Human Champion: | C8: Wario | H8: Animal Champion | I8: DK | N8: Monster Champion: | P8: Chrom
B9: Hardcore Champion: | C9: Bowser | H9: Special Champion: | I9: Incineroar | N9: Chaos Champion: | P9: Mega Man
B10: MITB Brawl: | C10: Samus | H10: MITB Melee: | N10: MITB Ultimate:
B12: Brawl Champion History | D12: Human Champion History | F12: Hardcore Champion History | H12: Unified Tag History | J12: Melee Champion History | L12: Animal Champion History | N12: Special Champion History | P12: Ultimate Champion History | R12: Monster Champion History | T12: Chaos Champion History | V12: Triple Crown Winners | X12: Smash Bros Championship History | Z12: Smash Series History | AB12: Two Major Winner | AD12: Three Major Winner
A13: 1 | B13: Pikachu | C13: 1 | D13: Mr. Game & Watch | E13: 1 | F13: Snake | G13: 1 | H13: Lucas + Ness | I13: 1 | J13: Kirby | K13: 1 | L13: Ice Climbers | M13: 1 | N13: Fox | O13: 1 | P13: Mr. Game & Watch | Q13: 1 | R13: Lucas | S13: 1 | T13: Greninja | U13: 1 | V13: Fox (Year 2 Ignition) | W13: 1 | X13: - | Y13: 1 | Z13: Toon Link/Simon Belmont (Brawl) | AA13: 1 | AB13: Pikachu (M/B) | AC13: 1 | AD13: Mario
A14: 2 | B14: Mario | C14: 2 | D14: Sonic | E14: 2 | F14: Luigi | G14: 2 | H14: Fox + Falco | I14: 2 | J14: Bowser | K14: 2 | L14: Wolf | M14: 2 | N14: Marth | O14: 2 | P14: Mario | Q14: 2 | R14: Ness | S14: 2 | T14: Snake | U14: 2 | V14: Ness (Year 2 Final Destination) | W14: 2 | X14: Wario | Y14: 2 | Z14: Ness/Ganondorf (Melee) | AA14: 2 | AB14: Luigi (M/B)
A15: 3 | B15: Pikachu | C15: 3 | D15: Mr. Game & Watch | E15: 3 | F15: Ganandorf | G15: 3 | H15: Lucas + Ness | I15: 3 | J15: Kirby | K15: 3 | L15: Mr. Game & Watch | M15: 3 | N15: Ness | O15: 3 | P15: Snake | Q15: 3 | R15: King Dedede | S15: 3 | T15: Captain Falcon | U15: 3 | V15: Toon Link (Year 3 King of the Hill) | W15: 3 | X15: Lucario | AA15: 3 | AB15: Kirby (M/B)
A16: 4 | B16: Wario | C16: 4 | D16: ROB | E16: 4 | F16: Luigi | G16: 4 | H16: Fox + Falco | I16: 4 | J16: Meta Knight | K16: 4 | L16: Toon Link | M16: 4 | N16: Wolf | O16: 4 | P16: Bowser | Q16: 4 | R16: Shulk | S16: 4 | T16: Shulk | U16: 4 | V16: Pikachu (Year 4 Great Race) | W16: 4 | X16: Lucario | AA16: 4 | AB16: Mr. Game & Watch (M/U)
A17: 5 | B17: Link | C17: 5 | D17: Olimar | E17: 5 | F17: ROB | G17: 5 | H17: Pikachu + Sonic | I17: 5 | J17: DK | K17: 5 | L17: Mr. Game & Watch | M17: 5 | N17: Mr. Game & Watch | O17: 5 | P17: Ness | Q17: 5 | R17: Dr. Mario | S17: 5 | T17: Captain Falcon | U17: 5 | V17: Ike (Year 5 BrawlMania) | W17: 5 | X17: Kirby | AA17: 5 | AB17: Bowser (M/U)
A18: 6 | B18: Diddy Kong | C18: 6 | D18: Ike | E18: 6 | F18: Wario | G18: 6 | H18: Fox + Falco | I18: 6 | J18: Pikachu | K18: 6 | L18: Toon Link | M18: 6 | N18: Bowser | O18: 6 | P18: King Dedede | Q18: 6 | R18: Inkling | S18: 6 | T18: Roy | U18: 6 | V18: Mr. Game & Watch (Year 6 Championship Scramble) | W18: 6 | X18: Wolf | AA18: 6 | AB18: Ness (B/U)
A19: 7 | B19: Mario | C19: 7 | D19: Olimar | E19: 7 | F19: Captain Falcon | G19: 7 | H19: Toon Link + Zelda | I19: 7 | J19: Kirby | K19: 7 | L19: Sonic | M19: 7 | N19: Pokemon Trainer | O19: 7 | P19: Mario | Q19: 7 | R19: Shulk | S19: 7 | T19: Mega Man | U19: 7 | V19: Lucas (Year 7 Final Destination) | W19: 7 | X19: Luigi
A20: 8 | B20: Diddy Kong | C20: 8 | D20: Ike | E20: 8 | F20: Lucario | G20: 8 | H20: Ike + Pikachu | I20: 8 | J20: Yoshi | K20: 8 | L20: Falco | M20: 8 | N20: Mr. Game & Watch | O20: 8 | P20: King Dedede | Q20: 8 | R20: Dr. Mario | S20: 8 | T20: Pac-Man
A21: 9 | B21: Luigi | C21: 9 | D21: Mario | E21: 9 | F21: Wario | G21: 9 | H21: King K. Rool + Mr. Game & Watch | I21: 9 | J21: Pit | K21: 9 | L21: Yoshi | M21: 9 | N21: Yoshi | O21: 9 | P21: Shulk | Q21: 9 | R21: Mr. Game & Watch | S21: 9 | T21: Mega Man
A22: 10 | B22: Fox | C22: 10 | D22: Ness | E22: 10 | F22: ROB | G22: 10 | H22: Ridley + Dark Samus | I22: 10 | J22: Luigi | K22: 10 | L22: Meta Knight | M22: 10 | N22: Olimar | O22: 10 | P22: Erdrick | Q22: 10 | R22: Dr. Mario
A23: 11 | B23: Toon Link | C23: 11 | D23: Diddy Kong | E23: 11 | F23: King Dedede | I23: 11 | J23: Meta Knight | K23: 11 | L23: Falco | M23: 11 | N23: King K. Rool | Q23: 11 | R23: Chrom
A24: 12 | B24: Ness | C24: 12 | D24: Ness | E24: 12 | F24: Mario | I24: 12 | J24: Luigi | K24: 12 | L24: Captain Falcon | M24: 12 | N24: DK
A25: 13 | B25: Toon Link | C25: 13 | D25: Sonic | E25: 13 | F25: Sonic | I25: 13 | J25: Mr. Game & Watch | K25: 13 | L25: Ike | M25: 13 | N25: Meta Knight
A26: 14 | B26: Captain Falcon | C26: 14 | D26: Diddy Kong | E26: 14 | F26: Marth | I26: 14 | J26: Kirby | K26: 14 | L26: Pikachu | M26: 14 | N26: Yoshi
A27: 15 | B27: Link | C27: 15 | D27: ROB | E27: 15 | F27: DK | I27: 15 | J27: Ike | K27: 15 | L27: Pit | M27: 15 | N27: Incineroar
A28: 16 | B28: Diddy Kong | C28: 16 | D28: Falco | E28: 16 | F28: Sonic | I28: 16 | J28: Meta Knight | K28: 16 | L28: Mario
A29: 17 | B29: Wario | C29: 17 | D29: Marth | E29: 17 | F29: Samus | I29: 17 | J29: Mario | K29: 17 | L29: Wario
A30: 18 | B30: Lucario | C30: 18 | D30: Robin | E30: 18 | F30: Kirby | I30: 18 | J30: Kirby | K30: 18 | L30: Dark Pit
A31: 19 | B31: ROB | C31: 19 | D31: Fox | E31: 19 | F31: Palutena | I31: 19 | J31: Meta Knight | K31: 19 | L31: Lucina
A32: 20 | B32: Pikachu | C32: 20 | D32: Falco | E32: 20 | F32: Samus | I32: 20 | J32: Luigi | K32: 20 | L32: Wolf
A33: 21 | B33: Diddy Kong | C33: 21 | D33: Robin | E33: 21 | F33: Palutena | I33: 21 | J33: Mario | K33: 21 | L33: Mewtwo
A34: 22 | B34: ROB | C34: 22 | D34: Marth | E34: 22 | F34: Simon Belmont | I34: 22 | J34: Pit | K34: 22 | L34: DK
A35: 23 | B35: Pikachu | C35: 23 | D35: Wario | E35: 23 | F35: Robin | I35: 23 | J35: Mario
A36: 24 | B36: Samus | E36: 24 | F36: Palutena | I36: 24 | J36: Pit
A37: 25 | B37: Wario | E37: 25 | F37: Bowser | I37: 25 | J37: Ganondorf
A38: 26 | B38: Diddy Kong | I38: 26 | J38: Cloud
A39: 27 | B39: Toon Link | I39: 27 | J39: Ganondorf
A40: 28 | B40: Kirby | I40: 28 | J40: Lucas
A41: 29 | B41: Toon Link
A42: 30 | B42: Marth
A43: 31 | B43: Toon Link
A44: 32 | B44: Diddy Kong
A45: 33 | B45: Toon Link
A46: 34 | B46: Wario
...

Sheet Award History
B1: Brawler of the Year | D1: Most Improved (Breakout) | F1: Most Disappointing | H1: Tag Team of the Year | J1: Match of the Year
A2: 1 | B2: Kirby | C2: 1 | D2: Wario | E2: 1 | F2: Ganondorf | G2: 1 | H2: Ness | I2: 1 | J2: Wolf vs. Pit vs. Falco
A3: 2 | B3: Luigi | C3: 2 | D3: Sonic | E3: 2 | F3: Marth | G3: + | H3: Lucas | I3: 2 | J3: Pikachu vs. DK
A4: 3 | B4: ROB | C4: 3 | D4: Falco | E4: 3 | F4: Wolf | G4: 2 | H4: Fox | I4: 3 | J4: Luigi vs. Link
A5: 4 | B5: Diddy Kong | C5: 4 | D5: Ike | E5: 4 | F5: Mr. Game & Watch | G5: + | H5: Falco | I5: 4 | J5: Samus vs. ROB
A6: 5 | B6: Toon Link | C6: 5 | D6: Mario | E6: 5 | F6: Bowser | G6: 3 | H6: Toon Link | I6: 5 | J6: Mario vs. Pit vs. Ike vs. Luigi
A7: 6 | B7: Cloud | C7: 6 | D7: King Dedede | E7: 6 | F7: Mewtwo | G7: + | H7: Zelda | I7: 6
G8: 4 | H8: Toon Link
G9: + | H9: Zelda
G10: 5 | H10: Ike
G11: + | H11: Pikachu
G12: 6 | H12: Ike
G13: + | H13: Pikachu

Sheet Career Stats
A1: Rank | B1: Name | C1: Wins | D1: Losses | E1: Win Percentage
A2: =RANK(Table18[[#This Row],[Win Percentage]],E:E) -> 1 | B2: Erdrick | C2: =SUM(VLOOKUP(B2,'Season 1 Stats'!$A$2:$C$500,2,FALSE),VLOOKUP(B2,'Season 2 Stats'!$A$2:$C$500,2,FALSE),VLOOKUP(B2,'Season 3 Stats'!$A$2:$C$500,2,FALSE),VLOOKUP(B2,'Season 4 Stats'!$A$2:$C$500,2,FALSE),VLOOKUP(B2,'Season 5 Stats'!$A$2:$C$500,2,FALSE),VLOOKUP(B2,'Season 6 Stats'!$A$2:$C$505,2,FALSE),VLOOKUP(B2,'Season 7 Stats'!$A$2:$C$508,2,FALSE)) -> 6 | D2: =SUM(VLOOKUP(B2,'Season 1 Stats'!$A$2:$C$500,3,FALSE),VLOOKUP(B2,'Season 2 Stats'!$A$2:$C$500,3,FALSE),VLOOKUP(B2,'Season 3 Stats'!$A$2:$C$500,3,FALSE),VLOOKUP(B2,'Season 4 Stats'!$A$2:$C$500,3,FALSE),VLOOKUP(B2,'Season 5 Stats'!$A$2:$C$500,3,FALSE),VLOOKUP(B2,'Season 6 Stats'!$A$2:$C$505,3,FALSE),VLOOKUP(B2,'Season 7 Stats'!$A$2:$C$508,3,FALSE)) -> 2 | E2: =IF(ISERROR(C2/(C2+D2)),0%,C2/(C2+D2)) -> 0.75
A3: =RANK(Table18[[#This Row],[Win Percentage]],E:E) -> 2 | B3: Cloud | C3: =SUM(VLOOKUP(B3,'Season 1 Stats'!$A$2:$C$500,2,FALSE),VLOOKUP(B3,'Season 2 Stats'!$A$2:$C$500,2,FALSE),VLOOKUP(B3,'Season 3 Stats'!$A$2:$C$500,2,FALSE),VLOOKUP(B3,'Season 4 Stats'!$A$2:$C$500,2,FALSE),VLOOKUP(B3,'Season 5 Stats'!$A$2:$C$500,2,FALSE),VLOOKUP(B3,'Season 6 Stats'!$A$2:$C$505,2,FALSE),VLOOKUP(B3,'Season 7 Stats'!$A$2:$C$508,2,FALSE)) -> 32 | D3: =SUM(VLOOKUP(B3,'Season 1 Stats'!$A$2:$C$500,3,FALSE),VLOOKUP(B3,'Season 2 Stats'!$A$2:$C$500,3,FALSE),VLOOKUP(B3,'Season 3 Stats'!$A$2:$C$500,3,FALSE),VLOOKUP(B3,'Season 4 Stats'!$A$2:$C$500,3,FALSE),VLOOKUP(B3,'Season 5 Stats'!$A$2:$C$500,3,FALSE),VLOOKUP(B3,'Season 6 Stats'!$A$2:$C$505,3,FALSE),VLOOKUP(B3,'Season 7 Stats'!$A$2:$C$508,3,FALSE)) -> 12 | E3: =IF(ISERROR(C3/(C3+D3)),0%,C3/(C3+D3)) -> 0.72727273
A4: =RANK(Table18[[#This Row],[Win Percentage]],E:E) -> 3 | B4: Kirby | C4: =SUM(VLOOKUP(B4,'Season 1 Stats'!$A$2:$C$500,2,FALSE),VLOOKUP(B4,'Season 2 Stats'!$A$2:$C$500,2,FALSE),VLOOKUP(B4,'Season 3 Stats'!$A$2:$C$500,2,FALSE),VLOOKUP(B4,'Season 4 Stats'!$A$2:$C$500,2,FALSE),VLOOKUP(B4,'Season 5 Stats'!$A$2:$C$500,2,FALSE),VLOOKUP(B4,'Season 6 Stats'!$A$2:$C$505,2,FALSE),VLOOKUP(B4,'Season 7 Stats'!$A$2:$C$508,2,FALSE)) -> 132 | D4: =SUM(VLOOKUP(B4,'Season 1 Stats'!$A$2:$C$500,3,FALSE),VLOOKUP(B4,'Season 2 Stats'!$A$2:$C$500,3,FALSE),VLOOKUP(B4,'Season 3 Stats'!$A$2:$C$500,3,FALSE),VLOOKUP(B4,'Season 4 Stats'!$A$2:$C$500,3,FALSE),VLOOKUP(B4,'Season 5 Stats'!$A$2:$C$500,3,FALSE),VLOOKUP(B4,'Season 6 Stats'!$A$2:$C$505,3,FALSE),VLOOKUP(B4,'Season 7 Stats'!$A$2:$C$508,3,FALSE)) -> 51 | E4: =IF(ISERROR(C4/(C4+D4)),0%,C4/(C4+D4)) -> 0.72131148
A5: =RANK(Table18[[#This Row],[Win Percentage]],E:E) -> 4 | B5: Toon Link | C5: =SUM(VLOOKUP(B5,'Season 1 Stats'!$A$2:$C$500,2,FALSE),VLOOKUP(B5,'Season 2 Stats'!$A$2:$C$500,2,FALSE),VLOOKUP(B5,'Season 3 Stats'!$A$2:$C$500,2,FALSE),VLOOKUP(B5,'Season 4 Stats'!$A$2:$C$500,2,FALSE),VLOOKUP(B5,'Season 5 Stats'!$A$2:$C$500,2,FALSE),VLOOKUP(B5,'Season 6 Stats'!$A$2:$C$505,2,FALSE),VLOOKUP(B5,'Season 7 Stats'!$A$2:$C$508,2,FALSE)) -> 138 | D5: =SUM(VLOOKUP(B5,'Season 1 Stats'!$A$2:$C$500,3,FALSE),VLOOKUP(B5,'Season 2 Stats'!$A$2:$C$500,3,FALSE),VLOOKUP(B5,'Season 3 Stats'!$A$2:$C$500,3,FALSE),VLOOKUP(B5,'Season 4 Stats'!$A$2:$C$500,3,FALSE),VLOOKUP(B5,'Season 5 Stats'!$A$2:$C$500,3,FALSE),VLOOKUP(B5,'Season 6 Stats'!$A$2:$C$505,3,FALSE),VLOOKUP(B5,'Season 7 Stats'!$A$2:$C$508,3,FALSE)) -> 66 | E5: =IF(ISERROR(C5/(C5+D5)),0%,C5/(C5+D5)) -> 0.67647059
A6: =RANK(Table18[[#This Row],[Win Percentage]],E:E) -> 5 | B6: Dark Pit | C6: =SUM(VLOOKUP(B6,'Season 1 Stats'!$A$2:$C$500,2,FALSE),VLOOKUP(B6,'Season 2 Stats'!$A$2:$C$500,2,FALSE),VLOOKUP(B6,'Season 3 Stats'!$A$2:$C$500,2,FALSE),VLOOKUP(B6,'Season 4 Stats'!$A$2:$C$500,2,FALSE),VLOOKUP(B6,'Season 5 Stats'!$A$2:$C$500,2,FALSE),VLOOKUP(B6,'Season 6 Stats'!$A$2:$C$505,2,FALSE),VLOOKUP(B6,'Season 7 Stats'!$A$2:$C$508,2,FALSE)) -> 31 | D6: =SUM(VLOOKUP(B6,'Season 1 Stats'!$A$2:$C$500,3,FALSE),VLOOKUP(B6,'Season 2 Stats'!$A$2:$C$500,3,FALSE),VLOOKUP(B6,'Season 3 Stats'!$A$2:$C$500,3,FALSE),VLOOKUP(B6,'Season 4 Stats'!$A$2:$C$500,3,FALSE),VLOOKUP(B6,'Season 5 Stats'!$A$2:$C$500,3,FALSE),VLOOKUP(B6,'Season 6 Stats'!$A$2:$C$505,3,FALSE),VLOOKUP(B6,'Season 7 Stats'!$A$2:$C$508,3,FALSE)) -> 15 | E6: =IF(ISERROR(C6/(C6+D6)),0%,C6/(C6+D6)) -> 0.67391304
A7: =RANK(Table18[[#This Row],[Win Percentage]],E:E) -> 6 | B7: Robin | C7: =SUM(VLOOKUP(B7,'Season 1 Stats'!$A$2:$C$500,2,FALSE),VLOOKUP(B7,'Season 2 Stats'!$A$2:$C$500,2,FALSE),VLOOKUP(B7,'Season 3 Stats'!$A$2:$C$500,2,FALSE),VLOOKUP(B7,'Season 4 Stats'!$A$2:$C$500,2,FALSE),VLOOKUP(B7,'Season 5 Stats'!$A$2:$C$500,2,FALSE),VLOOKUP(B7,'Season 6 Stats'!$A$2:$C$505,2,FALSE),VLOOKUP(B7,'Season 7 Stats'!$A$2:$C$508,2,FALSE)) -> 27 | D7: =SUM(VLOOKUP(B7,'Season 1 Stats'!$A$2:$C$500,3,FALSE),VLOOKUP(B7,'Season 2 Stats'!$A$2:$C$500,3,FALSE),VLOOKUP(B7,'Season 3 Stats'!$A$2:$C$500,3,FALSE),VLOOKUP(B7,'Season 4 Stats'!$A$2:$C$500,3,FALSE),VLOOKUP(B7,'Season 5 Stats'!$A$2:$C$500,3,FALSE),VLOOKUP(B7,'Season 6 Stats'!$A$2:$C$505,3,FALSE),VLOOKUP(B7,'Season 7 Stats'!$A$2:$C$508,3,FALSE)) -> 15 | E7: =IF(ISERROR(C7/(C7+D7)),0%,C7/(C7+D7)) -> 0.64285714
A8: =RANK(Table18[[#This Row],[Win Percentage]],E:E) -> 7 | B8: Luigi | C8: =SUM(VLOOKUP(B8,'Season 1 Stats'!$A$2:$C$500,2,FALSE),VLOOKUP(B8,'Season 2 Stats'!$A$2:$C$500,2,FALSE),VLOOKUP(B8,'Season 3 Stats'!$A$2:$C$500,2,FALSE),VLOOKUP(B8,'Season 4 Stats'!$A$2:$C$500,2,FALSE),VLOOKUP(B8,'Season 5 Stats'!$A$2:$C$500,2,FALSE),VLOOKUP(B8,'Season 6 Stats'!$A$2:$C$505,2,FALSE),VLOOKUP(B8,'Season 7 Stats'!$A$2:$C$508,2,FALSE)) -> 131 | D8: =SUM(VLOOKUP(B8,'Season 1 Stats'!$A$2:$C$500,3,FALSE),VLOOKUP(B8,'Season 2 Stats'!$A$2:$C$500,3,FALSE),VLOOKUP(B8,'Season 3 Stats'!$A$2:$C$500,3,FALSE),VLOOKUP(B8,'Season 4 Stats'!$A$2:$C$500,3,FALSE),VLOOKUP(B8,'Season 5 Stats'!$A$2:$C$500,3,FALSE),VLOOKUP(B8,'Season 6 Stats'!$A$2:$C$505,3,FALSE),VLOOKUP(B8,'Season 7 Stats'!$A$2:$C$508,3,FALSE)) -> 76 | E8: =IF(ISERROR(C8/(C8+D8)),0%,C8/(C8+D8)) -> 0.63285024
A9: =RANK(Table18[[#This Row],[Win Percentage]],E:E) -> 8 | B9: Pikachu | C9: =SUM(VLOOKUP(B9,'Season 1 Stats'!$A$2:$C$500,2,FALSE),VLOOKUP(B9,'Season 2 Stats'!$A$2:$C$500,2,FALSE),VLOOKUP(B9,'Season 3 Stats'!$A$2:$C$500,2,FALSE),VLOOKUP(B9,'Season 4 Stats'!$A$2:$C$500,2,FALSE),VLOOKUP(B9,'Season 5 Stats'!$A$2:$C$500,2,FALSE),VLOOKUP(B9,'Season 6 Stats'!$A$2:$C$505,2,FALSE),VLOOKUP(B9,'Season 7 Stats'!$A$2:$C$508,2,FALSE)) -> 132 | D9: =SUM(VLOOKUP(B9,'Season 1 Stats'!$A$2:$C$500,3,FALSE),VLOOKUP(B9,'Season 2 Stats'!$A$2:$C$500,3,FALSE),VLOOKUP(B9,'Season 3 Stats'!$A$2:$C$500,3,FALSE),VLOOKUP(B9,'Season 4 Stats'!$A$2:$C$500,3,FALSE),VLOOKUP(B9,'Season 5 Stats'!$A$2:$C$500,3,FALSE),VLOOKUP(B9,'Season 6 Stats'!$A$2:$C$505,3,FALSE),VLOOKUP(B9,'Season 7 Stats'!$A$2:$C$508,3,FALSE)) -> 78 | E9: =IF(ISERROR(C9/(C9+D9)),0%,C9/(C9+D9)) -> 0.62857143
A10: =RANK(Table18[[#This Row],[Win Percentage]],E:E) -> 9 | B10: Wario | C10: =SUM(VLOOKUP(B10,'Season 1 Stats'!$A$2:$C$500,2,FALSE),VLOOKUP(B10,'Season 2 Stats'!$A$2:$C$500,2,FALSE),VLOOKUP(B10,'Season 3 Stats'!$A$2:$C$500,2,FALSE),VLOOKUP(B10,'Season 4 Stats'!$A$2:$C$500,2,FALSE),VLOOKUP(B10,'Season 5 Stats'!$A$2:$C$500,2,FALSE),VLOOKUP(B10,'Season 6 Stats'!$A$2:$C$505,2,FALSE),VLOOKUP(B10,'Season 7 Stats'!$A$2:$C$508,2,FALSE)) -> 129 | D10: =SUM(VLOOKUP(B10,'Season 1 Stats'!$A$2:$C$500,3,FALSE),VLOOKUP(B10,'Season 2 Stats'!$A$2:$C$500,3,FALSE),VLOOKUP(B10,'Season 3 Stats'!$A$2:$C$500,3,FALSE),VLOOKUP(B10,'Season 4 Stats'!$A$2:$C$500,3,FALSE),VLOOKUP(B10,'Season 5 Stats'!$A$2:$C$500,3,FALSE),VLOOKUP(B10,'Season 6 Stats'!$A$2:$C$505,3,FALSE),VLOOKUP(B10,'Season 7 Stats'!$A$2:$C$508,3,FALSE)) -> 86 | E10: =IF(ISERROR(C10/(C10+D10)),0%,C10/(C10+D10)) -> 0.6
A11: =RANK(Table18[[#This Row],[Win Percentage]],E:E) -> 10 | B11: ROB | C11: =SUM(VLOOKUP(B11,'Season 1 Stats'!$A$2:$C$500,2,FALSE),VLOOKUP(B11,'Season 2 Stats'!$A$2:$C$500,2,FALSE),VLOOKUP(B11,'Season 3 Stats'!$A$2:$C$500,2,FALSE),VLOOKUP(B11,'Season 4 Stats'!$A$2:$C$500,2,FALSE),VLOOKUP(B11,'Season 5 Stats'!$A$2:$C$500,2,FALSE),VLOOKUP(B11,'Season 6 Stats'!$A$2:$C$505,2,FALSE),VLOOKUP(B11,'Season 7 Stats'!$A$2:$C$508,2,FALSE)) -> 124 | D11: =SUM(VLOOKUP(B11,'Season 1 Stats'!$A$2:$C$500,3,FALSE),VLOOKUP(B11,'Season 2 Stats'!$A$2:$C$500,3,FALSE),VLOOKUP(B11,'Season 3 Stats'!$A$2:$C$500,3,FALSE),VLOOKUP(B11,'Season 4 Stats'!$A$2:$C$500,3,FALSE),VLOOKUP(B11,'Season 5 Stats'!$A$2:$C$500,3,FALSE),VLOOKUP(B11,'Season 6 Stats'!$A$2:$C$505,3,FALSE),VLOOKUP(B11,'Season 7 Stats'!$A$2:$C$508,3,FALSE)) -> 83 | E11: =IF(ISERROR(C11/(C11+D11)),0%,C11/(C11+D11)) -> 0.59903382
A12: =RANK(Table18[[#This Row],[Win Percentage]],E:E) -> 11 | B12: Shulk | C12: =SUM(VLOOKUP(B12,'Season 1 Stats'!$A$2:$C$500,2,FALSE),VLOOKUP(B12,'Season 2 Stats'!$A$2:$C$500,2,FALSE),VLOOKUP(B12,'Season 3 Stats'!$A$2:$C$500,2,FALSE),VLOOKUP(B12,'Season 4 Stats'!$A$2:$C$500,2,FALSE),VLOOKUP(B12,'Season 5 Stats'!$A$2:$C$500,2,FALSE),VLOOKUP(B12,'Season 6 Stats'!$A$2:$C$505,2,FALSE),VLOOKUP(B12,'Season 7 Stats'!$A$2:$C$508,2,FALSE)) -> 25 | D12: =SUM(VLOOKUP(B12,'Season 1 Stats'!$A$2:$C$500,3,FALSE),VLOOKUP(B12,'Season 2 Stats'!$A$2:$C$500,3,FALSE),VLOOKUP(B12,'Season 3 Stats'!$A$2:$C$500,3,FALSE),VLOOKUP(B12,'Season 4 Stats'!$A$2:$C$500,3,FALSE),VLOOKUP(B12,'Season 5 Stats'!$A$2:$C$500,3,FALSE),VLOOKUP(B12,'Season 6 Stats'!$A$2:$C$505,3,FALSE),VLOOKUP(B12,'Season 7 Stats'!$A$2:$C$508,3,FALSE)) -> 17 | E12: =IF(ISERROR(C12/(C12+D12)),0%,C12/(C12+D12)) -> 0.5952381
A13: =RANK(Table18[[#This Row],[Win Percentage]],E:E) -> 12 | B13: Dr. Mario | C13: =SUM(VLOOKUP(B13,'Season 1 Stats'!$A$2:$C$500,2,FALSE),VLOOKUP(B13,'Season 2 Stats'!$A$2:$C$500,2,FALSE),VLOOKUP(B13,'Season 3 Stats'!$A$2:$C$500,2,FALSE),VLOOKUP(B13,'Season 4 Stats'!$A$2:$C$500,2,FALSE),VLOOKUP(B13,'Season 5 Stats'!$A$2:$C$500,2,FALSE),VLOOKUP(B13,'Season 6 Stats'!$A$2:$C$505,2,FALSE),VLOOKUP(B13,'Season 7 Stats'!$A$2:$C$508,2,FALSE)) -> 25 | D13: =SUM(VLOOKUP(B13,'Season 1 Stats'!$A$2:$C$500,3,FALSE),VLOOKUP(B13,'Season 2 Stats'!$A$2:$C$500,3,FALSE),VLOOKUP(B13,'Season 3 Stats'!$A$2:$C$500,3,FALSE),VLOOKUP(B13,'Season 4 Stats'!$A$2:$C$500,3,FALSE),VLOOKUP(B13,'Season 5 Stats'!$A$2:$C$500,3,FALSE),VLOOKUP(B13,'Season 6 Stats'!$A$2:$C$505,3,FALSE),VLOOKUP(B13,'Season 7 Stats'!$A$2:$C$508,3,FALSE)) -> 18 | E13: =IF(ISERROR(C13/(C13+D13)),0%,C13/(C13+D13)) -> 0.58139535
... A74: =RANK(Table18[[#This Row],[Win Percentage]],E:E) -> 73 | B74: Pichu | C74: =SUM(VLOOKUP(B74,'Season 1 Stats'!$A$2:$C$500,2,FALSE),VLOOKUP(B74,'Season 2 Stats'!$A$2:$C$500,2,FALSE),VLOOKUP(B74,'Season 3 Stats'!$A$2:$C$500,2,FALSE),VLOOKUP(B74,'Season 4 Stats'!$A$2:$C$500,2,FALSE),VLOOKUP(B74,'Season 5 Stats'!$A$2:$C$500,2,FALSE),VLOOKUP(B74,'Season 6 Stats'!$A$2:$C$505,2,FALSE),VLOOKUP(B74,'Season 7 Stats'!$A$2:$C$508,2,FALSE)) -> 0 | D74: =SUM(VLOOKUP(B74,'Season 1 Stats'!$A$2:$C$500,3,FALSE),VLOOKUP(B74,'Season 2 Stats'!$A$2:$C$500,3,FALSE),VLOOKUP(B74,'Season 3 Stats'!$A$2:$C$500,3,FALSE),VLOOKUP(B74,'Season 4 Stats'!$A$2:$C$500,3,FALSE),VLOOKUP(B74,'Season 5 Stats'!$A$2:$C$500,3,FALSE),VLOOKUP(B74,'Season 6 Stats'!$A$2:$C$505,3,FALSE),VLOOKUP(B74,'Season 7 Stats'!$A$2:$C$508,3,FALSE)) -> 22 | E74: =IF(ISERROR(C74/(C74+D74)),0%,C74/(C74+D74)) -> 0

Sheet Ultimate Tourney
A1: Pikachu (9) | D1: Ultimate | F1: Incineroar (8) | I1: Monster | N1: Chaos
B2: Shulk | G2: Peach | L2: King Dedede (6)
A3: Shulk (5) | F3: Peach (2)
C4: MGW | H4: Lucas | M4: Snake
A5: Samus (7) | F5: Lucas (7) | K5: Pichu (3)
B6: MGW | G6: Lucas | L6: Snake
A7: MGW (8) | F7: Ness (8) | K7: Snake (6)
D8: MGW | I8: Lucas | N8: Greninja
A9: Mewtwo (8) | F9: Captain Falcon (6) | K9: Greninja (7)
B10: Falco | G10: Captain Falcon | L10: Greninja
A11: Falco (6) | F11: Mega Man (6) | K11: Daisy (2)
C12: Mario | H12: Bowser | M12: Greninja
A13: Yoshi (6) | F13: Jigglypuff (1)
B14: Mario | G14: Bowser | L14: Chrom (8)
A15: Mario (9) | F15: Bowser (7)
A18: Ethan's predictions
A20: Pikachu (9) | D20: Ultimate | F20: Incineroar (8) | I20: Monster | N20: Chaos
B21: Pikachu | G21: Incineroar | L21: King Dedede (6)
A22: Shulk (5) | F22: Peach (2)
C23: Pikachu | H23: Incineroar | M23: Snake
A24: Samus (7) | F24: Lucas (7) | K24: Pichu (3)
B25: MG&W | G25: Ness | L25: Snake
A26: MGW (8) | F26: Ness (8) | K26: Snake (6)
D27: Pikachu | I27: Incineroar | N27: Chrom
A28: Mewtwo (8) | F28: Captain Falcon (6) | K28: Greninja (7)
B29: Mewtwo | G29: Captain Falcon | L29: Greninja
A30: Falco (6) | F30: Mega Man (6) | K30: Daisy (2)
C31: Mario | H31: Bowser | M31: Chrom
A32: Yoshi (6) | F32: Jigglypuff (1)
B33: Mario | G33: Bowser | L33: Chrom (8)
A34: Mario (9) | F34: Bowser (7)
A36: Ian's predicitions
A38: Pikachu (9) | D38: Ultimate | F38: Incineroar (8) | I38: Monster | N38: Chaos
B39: Pikachu | G39: Incineroar | L39: King Dedede (6)
A40: Shulk (5) | F40: Peach (2)
C41: Pikachu | H41: Ness | M41: King Dedede
A42: Samus (7) | F42: Lucas (7) | K42: Pichu (3)
B43: MGW | G43: Ness | L43: Snake
A44: MGW (8) | F44: Ness (8) | K44: Snake (6)
D45: Mario | I45: Ness | N45: Greninja
...

Sheet Season 7
A1: Month 1 | B1: Royal Rumble | L1: Month 2 | M1: Pokeslam | U1: Month 3 | V1: Brawlmania | AD1: Month 4 | AE1: Money in the Bank | AM1: Month 5 | AN1: Ignition | AT1: Month 6 | AU1: Summer Slam | BA1: Month 7 | BB1: Final Destination Tournament | BH1: Month 8 | BI1: The Great Race | BJ1: Erdrick Joins Smash Bros. | BK1: TRADE ALERT: | BQ1: Month 9 | BR1: King of the Hill | BX1: Month 10 | BY1: Smash Series | CH1: Month 11 | CI1: Championship Cruise | CO1: Month 12 | CP1: Championship Scramble
BK2: Ultimate trades Dr. Mario & Captain Falcon to Brawl for Erdrick & Ken
B3: Brawl | C3: Kongo Jungle | M3: Brawl | N3: Temple | V3: Brawl | W3: Mushroom Kingdom II | AE3: Brawl | AF3: Frigate Orpheon | AN3: Brawl | AO3: Shadow Moses Island | AU3: Brawl | AV3: 3D Land | BB3: Brawl | BC3: Magicant (No Hazards) | BI3: Brawl | BJ3: Mushroom Kingdom U | BR3: Brawl | BS3: Garden of Hope | BY3: Brawl | BZ3: Wily Castle | CI3: Brawl | CJ3: Dracula's Castle | CP3: Brawl | CQ3: Lylat Cruise
A4: Spot in Royal Rumble | B4: 1 | C4: Simon Belmont | D4: Robin - W | M4: 1 | N4: Link - W | O4: Daisy | V4: 1 | W4: Pokemon Trainer | X4: ROB - W | AD4: Spot in MITB | AE4: 1 | AF4: Robin | AG4: Ice Climbers - W | AN4: 1 | AO4: Daisy | AP4: Kirby - W | AU4: 1 | AV4: Luigi - W | AW4: Rosalina & Luma | BB4: 1 | BC4: Bowser - W | BD4: Pokemon Trainer | BI4: 1 | BJ4: Diddy Kong - W | BK4: Palutena | BR4: 1 | BS4: Dr. Mario | BT4: Palutena - W | BY4: 1 | BZ4: Simon Belmont - W | CA4: Marth | CI4: 1 | CP4: 1
C5: 0 | D5: 2 | N5: 2 | O5: 0 | W5: 0 | X5: 2 | AF5: 0 | AG5: 2 | AO5: 0 | AP5: 3 | AV5: 2 | AW5: 0 | BC5: 1 | BD5: 0 | BJ5: 2 | BK5: 0 | BS5: 0 | BT5: 1 | BZ5: 2 | CA5: 0
B6: 2 | C6: Ken | D6: Marth - W | M6: 2 | N6: Wii Fit Trainer | O6: Ken - W | V6: 2 | W6: Ryu | X6: Wario - W | AE6: 2 | AF6: Ryu - W | AG6: Jigglypuff | AN6: 2 | AO6: Palutena - W | AP6: Ice Climbers | AU6: 2 | AV6: Sonic - W | AW6: Pokemon Trainer | BB6: 2 | BC6: Palutena | BD6: Marth - W | BI6: 2 | BJ6: Sheik | BK6: Bowser Jr. - W | BR6: 2 | BS6: Bowser - W | BT6: Simon Belmont | BY6: 2 | BZ6: Bowser - W | CA6: Sheik | CI6: 2 | CP6: 2
C7: 0 | D7: 3 | N7: 0 | O7: 2 | W7: 0 | X7: 2 | AF7: 1 | AG7: 0 | AO7: 1 | AP7: 0 | AV7: 2 | AW7: 0 | BC7: 0 | BD7: 1 | BJ7: 0 | BK7: 1 | BS7: 1 | BT7: 0 | BZ7: 2 | CA7: 0
B8: 3 | C8: ROB - W | D8: Wii Fit Trainer | M8: 3 | N8: Palutena - W | O8: Ryu | V8: 3 | W8: Marth - W | X8: Roaslina & Luma | AD8: #1 contender Human | AE8: 3 | AF8: Rosalina & Luma | AG8: Wii Fit Trainer - W | AN8: 3 | AO8: Bowser Jr. | AP8: Marth - W | AU8: 3 | AV8: Wario - W | AW8: Dark Samus | BB8: 3 | BC8: Kirby - W | BD8: Falco | BI8: 3 | BJ8: Sonic | BK8: Dark Samus - W | BR8: 3 | BS8: Pichu | BT8: Jigglypuff - W | BY8: 3 | BZ8: Captain Falcon - W | CA8: Sonic | CI8: 3 | CP8: 3
C9: 2 | D9: 0 | N9: 1 | O9: 0 | W9: 3 | X9: 0 | AF9: 0 | AG9: 2 | AO9: 0 | AP9: 1 | AV9: 1 | AW9: 0 | BC9: 1 | BD9: 0 | BJ9: 0 | BK9: 2 | BS9: 0 | BT9: 1 | BZ9: 1 | CA9: 0
B10: 4 | C10: Fox | D10: Toon Link - W | M10: 4 | N10: Kirby - W | O10: Fox | V10: 4 | W10: Palutena - W | X10: Ice Climbers | AE10: 4 | AF10: Marth - W | AG10: Falco | AN10: 4 | AO10: Link - W | AP10: Falco | AU10: 4 | AV10: Jigglypuff | AW10: Bowser - W | BA10: #16 seed | BB10: 4 | BC10: Pichu | BD10: Jigglypuff - W | BE10: Rosalina & Luma | BF10: Ryu | BI10: 4 | BJ10: Captain Falcon - W | BK10: Young Link | BR10: 4 | BS10: Robin - W | BT10: Sheik | BY10: 4 | BZ10: Corrin | CA10: Bowser Jr. - W | CI10: 4 | CP10: 4
C11: 0 | D11: 3 | N11: 1 | O11: 0 | W11: 2 | X11: 0 | AF11: 2 | AG11: 0 | AO11: 3 | AP11: 0 | AV11: 0 | AW11: 2 | BC11: 0 | BD11: 1 | BE11: 0 | BF11: 0 | BJ11: 2 | BK11: 0 | BS11: 1 | BT11: 0 | BZ11: 0 | CA11: 1
A12: #1 Contender Hardcore | B12: 5 | C12: Wolf | D12: Samus - W | L12: #1 Contender Human | M12: 5 | N12: Ice Climbers | O12: Robin - W | U12: Spot in Hardcore | V12: 5 | W12: Samus - W | X12: Simon Belmont | AD12: Spot in MITB | AE12: 5 | AF12: Palutena | AG12: Samus - W | AM12: #1 Contender Hardcore | AN12: 5 | AO12: Simon Belmont - W | AP12: Wolf | AT12: #1 Contender Human | AU12: 5 | AV12: Diddy Kong | AW12: Palutena - W | BA12: #15 seed | BB12: 5 | BC12: Corrin - W | BD12: Bowser Jr. | BE12: Young Link | BF12: Sheik | BH12: Spot in Brawl | BI12: 5 | BJ12: Kirby - W | BK12: Bowser | BQ12: #1 Contender Hardcore | BR12: 5 | BS12: Diddy Kong | BT12: Captain Falcon - W | BY12: 5 | BZ12: Luigi | CA12: Dr. Mario - W | CI12: 5 | CP12: 5
C13: 0 | D13: 0 | N13: 0 | O13: 2 | W13: 2 | X13: -2 | AF13: 0 | AG13: 1 | AO13: 1 | AP13: -1 | AV13: 0 | AW13: 2 | BC13: 1 | BD13: 0 | BE13: 0 | BF13: 0 | BJ13: 1 | BK13: 0 | BS13: -2 | BT13: 2 | BZ13: 0 | CA13: 1
B15: Melee | C15: Battlefield | M15: Melee | N15: Jungle Japes | V15: Melee | W15: Pokemon Stadium 2 | AE15: Melee | AF15: Bridge of Eldin | AN15: Melee | AO15: New Pork City | AU15: Melee | AV15: Golden Plains | BB15: Melee | BC15: Arena Ferox | BI15: Melee | BJ15: Mario Galaxy | BR15: Melee | BS15: Town and City | BY15: Melee | BZ15: PAC-LAND | CI15: Melee | CJ15: Mementos | CP15: Melee | CQ15: Fourside
B16: 1 | C16: Joker - W | D16: Lucas | M16: 1 | N16: DK - W | O16: Mewtwo | V16: 1 | W16: Olimar | X16: King K. Rool - W | AE16: 1 | AF16: Isabelle | AG16: Olimar - W | AN16: 1 | AO16: Dark Samus | AP16: DK - W | AU16: 1 | AV16: Wolf - W | AW16: Isabelle | BB16: 1 | BC16: Ganondorf - W | BD16: Greninja | BI16: 1 | BJ16: Daisy | BK16: Mewtwo - W | BR16: 1 | BS16: Mr. Game & Watch | BT16: Isabelle - W | BY16: 1 | BZ16: Greninja | CA16: DK - W | CI16: 1 | CP16: 1
C17: 1 | D17: 0 | N17: 2 | O17: 0 | W17: 0 | X17: 2 | AF17: 0 | AG17: 1 | AO17: 0 | AP17: 2 | AV17: 1 | AW17: 0 | BA17: 0% Match | BC17: 3 | BD17: 0 | BJ17: 0 | BK17: 2 | BS17: 0 | BT17: 1 | BZ17: 0 | CA17: 2
B18: 2 | C18: Mewtwo | D18: Incineroar - W | M18: 2 | N18: Lucas - W | O18: Olimar | V18: 2 | W18: Lucario | X18: Mewtwo - W | AE18: 2 | AF18: Lucario - W | AG18: Duck Hunt | AN18: 2 | AO18: Bayonetta | AP18: Cloud - W | AU18: 2 | AV18: Greninja - W | AW18: Daisy | BB18: 2 | BC18: Lucina | BD18: Lucas - W | BI18: 2 | BJ18: Ridley - W | BK18: Isabelle | BR18: 2 | BS18: Lucina - W | BT18: Greninja | BY18: 2 | BZ18: Ridley - W | CA18: Mr. Game & Watch | CI18: 2 | CP18: 2
C19: 0 | D19: 1 | N19: 2 | O19: 0 | W19: 0 | X19: 3 | AF19: 1 | AG19: 0 | AO19: 0 | AP19: 2 | AV19: 2 | AW19: 0 | BC19: 0 | BD19: 1 | BJ19: 3 | BK19: 0 | BS19: 2 | BT19: 0 | BZ19: 1 | CA19: 0
B20: 3 | C20: Pit - W | D20: Lucina | M20: 3 | N20: Joker - W | O20: Lucina | V20: 3 | W20: Lucina | X20: Lucas - W | AD20: Spot in MITB | AE20: 3 | AF20: Diddy Kong - W | AG20: Corrin | AN20: 3 | AO20: Pit | AP20: Dark Pit - W | AU20: 3 | AV20: Pirahna Plant | AW20: Richter Belmont - W | BB20: 3 | BC20: Incineroar - W | BD20: King K. Rool | BI20: 3 | BJ20: Richter Belmont - W | BK20: Olimar | BR20: 3 | BS20: Yoshi - W | BT20: Olimar | BY20: 3 | BZ20: Zelda - W | CA20: Pirahna Plant | CI20: 3 | CP20: 3
C21: 1 | D21: 0 | N21: 1 | O21: 0 | W21: 0 | X21: 2 | AF21: 1 | AG21: 0 | AO21: 0 | AP21: 2 | AV21: 0 | AW21: 3 | BC21: 1 | BD21: 0 | BJ21: 3 | BK21: 0 | BS21: 2 | BT21: 0 | BZ21: 3 | CA21: 0
A22: Spot in Royal Rumble | B22: 4 | C22: Luigi - W | D22: Lucario | L22: #1 contender Special | M22: 4 | N22: Zelda | O22: Incineroar - W | V22: 4 | W22: Pit - W | X22: DK | AD22: Spot in MITB | AE22: 4 | AF22: Mewtwo - W | AG22: Dark Samus | AN22: 4 | AO22: Lucas | AP22: Joker - W | AT22: #1 contender Special | AU22: 4 | AV22: Mewtwo - W | AW22: DK | BA22: #16 seed | BB22: 4 | BC22: Bayonetta | BD22: Duck Hunt | BE22: Isabelle | BF22: Richter Belmont - W | BH22: Spot in Animal | BI22: 4 | BJ22: Lucina - W | BK22: Zelda | BQ22: #1 contender Animal | BR22: 4 | BS22: Richet Belmont | BT22: Mewtwo - W | BY22: 4 | BZ22: Wolf - W | CA22: Dark Pit | CI22: 4 | CP22: 4
A23: Absolute beatdown | C23: 3 | D23: 0 | L23: Chaos Match | N23: 0 | O23: 0 | W23: 1 | X23: 0 | AF23: 1 | AG23: 0 | AO23: 0 | AP23: 1 | AT23: 300% match | AV23: 3 | AW23: 0 | BC23: 0 | BD23: 0 | BE23: 0 | BF23: 1 | BJ23: 2 | BK23: 0 | BS23: 0 | BT23: 1 | BZ23: 2 | CA23: 0
A24: #1 contender Animal | B24: 5 | C24: Diddy Kong - W | D24: Corrin | M24: 5 | N24: Pit - W | O24: Diddy Kong | U24: #1 contender Special | V24: 5 | W24: Yoshi - W | X24: Ridley | AD24: #1 contender Animal | AE24: 5 | AF24: Zelda | AG24: Lucina - W | AM24: #1 contender Animal | AN24: 5 | AO24: Mewtwo | AP24: King K. Rool - W | AU24: 5 | AV24: Ness - W | AW24: Link | BA24: #15 seed | BB24: 5 | BC24: Olimar - W | BD24: Pirahna Plant | BE24: Daisy | BF24: Zelda | BH24: Spot in Melee | BI24: 5 | BJ24: Ganondorf - W | BK24: Mr. Game & Watch | BR24: 5 | BS24: Cloud | BT24: Ganondorf - W | BY24: 5 | BZ24: Ganondorf - W | CA24: Cloud | CI24: 5 | CP24: 5
C25: 1 | D25: 0 | N25: 2 | O25: 0 | U25: Flower Match | W25: 2 | X25: 0 | AF25: 0 | AG25: 1 | AO25: 0 | AP25: 2 | AV25: 2 | AW25: 0 | BC25: 1 | BD25: 0 | BE25: 0 | BF25: 0 | BJ25: 3 | BK25: 0 | BS25: 0 | BT25: 1 | BZ25: 1 | CA25: 0
B27: Ultimate | C27: Peach's Castle | M27: Ultimate | N27: Great Bay | V27: Ultimate | W27: Onett | AE27: Ultimate | AF27: Norfair | AN27: Ultimate | AO27: Skyworld | AU27: Ultimate | AV27: Paper Mario | BB27: Ultimate | BC27: Reset Bomb Forest | BI27: Ultimate | BJ27: Mario Circuit | BR27: Ultimate | BS27: Wii Fit Studio | BY27: Ultimate | BZ27: Super Mario Maker | CI27: Ultimate | CJ27: Summit | CP27: Ultimate | CQ27: Jungle Japes
B28: 1 | C28: Peach | D28: Pac-Man - W | M28: 1 | N28: Pichu | O28: Sheik - W | V28: 1 | W28: Sheik | X28: Greninja - W | AD28: Battle of the Career Winless | AE28: 1 | AF28: Pichu | AG28: Pirahna Plant - W | AN28: 1 | AO28: Inkling | AP28: Villager - W | AU28: 1 | AV28: Chrom - W | AW28: Meta Knight | BB28: 1 | BC28: Ike - W | BD28: Snake | BI28: 1 | BJ28: Meta Knight | BK28: Wii Fit Trainer - W | BR28: 1 | BS28: Ice Climbers - W | BT28: Little Mac | BY28: 1 | BZ28: Inkling - W | CA28: Snake | CI28: 1 | CP28: 1
C29: 0 | D29: 2 | N29: 0 | O29: 2 | W29: 0 | X29: 2 | AF29: 0 | AG29: 3 | AO29: 0 | AP29: 1 | AV29: 1 | AW29: 0 | BC29: 2 | BD29: 0 | BJ29: 0 | BK29: 1 | BS29: 3 | BT29: 0 | BZ29: 1 | CA29: 0
B30: 2 | C30: Pirahna Plant | D30: Villager - W | M30: 2 | N30: Ness - W | O30: Inkling | V30: 2 | W30: Shulk - W | X30: Pac-Man | AE30: 2 | AF30: Mega Man | AG30: King Dedede - W | AN30: 2 | AO30: Bowser - W | AP30: Little Mac | AU30: 2 | AV30: ROB | AW30: Captain Falcon - W | BB30: 2 | BC30: Mega Man - W | BD30: Wii Fit Trainer | BI30: 2 | BJ30: Pac-Man - W | BK30: Lucario | BR30: 2 | BS30: Pikachu | BT30: Meta Knight - W | BY30: 2 | BZ30: Fox - W | CA30: Little Mac | CI30: 2 | CP30: 2
C31: 0 | D31: 3 | N31: 2 | O31: 0 | W31: 2 | X31: 0 | AF31: 0 | AG31: 2 | AO31: 2 | AP31: 0 | AV31: 0 | AW31: 1 | BC31: 2 | BD31: 0 | BJ31: 1 | BK31: 0 | BS31: 0 | BT31: 1 | BZ31: 1 | CA31: 0
B32: 3 | C32: Mega Man | D32: Snake - W | M32: 3 | N32: Young Link | O32: Dr. Mario - W | V32: 3 | W32: Pikachu - W | X32: Little Mac | AD32: Spot in MITB | AE32: 3 | AF32: Chrom - W | AG32: Snake | AN32: 3 | AO32: Pikachu - W | AP32: Greninja | AU32: 3 | AV32: Lucario - W | AW32: Ice Climbers | BB32: 3 | BC32: ROB - W | BD32: Lucario | BI32: 3 | BJ32: Joker - W | BK32: Ice Climbers | BQ32: #1 Contender Chaos | BR32: 3 | BS32: Mega Man - W | BT32: Wii Fit Trainer | BY32: 3 | BZ32: Mega Man - W | CA32: Meta Knight | CI32: 3 | CP32: 3
C33: 0 | D33: 1 | N33: 0 | O33: 2 | W33: 1 | X33: 0 | AF33: 1 | AG33: 0 | AO33: 2 | AP33: 0 | AV33: 1 | AW33: 0 | BC33: 1 | BD33: 0 | BJ33: 1 | BK33: 0 | BS33: 0 | BT33: 0 | BZ33: 2 | CA33: 0
A34: #1 contender Monster | B34: 4 | C34: Dr. Mario | D34: Shulk - W | M34: 4 | N34: Captain Falcon | O34: Greninja - W | V34: 4 | W34: Ike | X34: Young Link - W | AD34: Spot in MITB | AE34: 4 | AF34: Greninja | AG34: Shulk - W | AN34: 4 | AO34: Ike - W | AP34: Chrom | AU34: 4 | AV34: Pit | AW34: Fox - W | BA34: #16 seed | BB34: 4 | BC34: Peach | BD34: Inkling | BE34: Little Mac | BF34: Fox - W | BH34: Spot in Monster | BI34: 4 | BJ34: Ken - W | BK34: Snake | BR34: 4 | BS34: Erdrick - W | BT34: ROB | BY34: 4 | BZ34: Ike - W | CA34: Roy | CI34: 4 | CP34: 4
C35: 0 | D35: 1 | N35: 0 | O35: 1 | W35: 0 | X35: 1 | AD35: 3 -1 Comeback | AF35: 0 | AG35: 1 | AO35: 1 | AP35: 0 | AV35: 0 | AW35: 1 | BC35: 0 | BD35: 0 | BE35: 0 | BF35: 1 | BJ35: 1 | BK35: 0 | BS35: 2 | BT35: 0 | BZ35: 1 | CA35: 0
A36: Spot in Royal Rumble | B36: 5 | C36: Ness - W | D36: Roy | L36: #1 Contender Chaos | M36: 5 | N36: Pac-Man | O36: Bowser - W | U36: #1 contender Ultimate | V36: 5 | W36: Ness | X36: King Dedede - W | AD36: #1 Contender Monster | AE36: 5 | AF36: Mr. Game & Watch - W | AG36: Young Link | AM36: #1 contender Chaos | AN36: 5 | AO36: Roy - W | AP36: Captain Falcon | AT36: #1 Contender Chaos | AU36: 5 | AV36: Joker - W | AW36: Ike | BA36: #15 seed | BB36: 5 | BC36: Meta Knight - W | BD36: Ice Climbers | BE36: Pac-Man | BF36: Villager | BH36: Spot in Ultimate | BI36: 5 | BJ36: Erdrick - W | BK36: Pit | BR36: 5 | BS36: Joker | BT36: Mario - W | BX36: #1 contender Ultimate | BY36: 5 | BZ36: Mario | CA36: Erdrick - W | CI36: 5 | CP36: 5
C37: 2 | D37: 0 | N37: -2 | O37: 2 | W37: 0 | X37: 1 | AF37: 1 | AG37: 0 | AO37: 2 | AP37: -2 | AV37: 1 | AW37: -1 | BC37: 2 | BD37: 0 | BE37: 0 | BF37: 0 | BJ37: 2 | BK37: 0 | BS37: 0 | BT37: 2 | BZ37: 0 | CA37: 2
B39: Brawl | C39: Saffron City | M39: Brawl | N39: Yoshi's Story | V39: Brawl | W39: Fourside | AE39: Brawl | AF39: Lylat Cruise | AN39: Brawl | AO39: Spear Pillar | AU39: Brawl | AV39: Gerudo Valley | BB39: Brawl | BC39: Tortimer Island | BI39: Brawl | BJ39: Skyloft | BR39: Brawl | BS39: Gaur Plain | BY39: Brawl | BZ39: Suzaku Castle | CI39: Brawl | CJ39: Big Blue | CP39: Brawl | CQ39: Figure -8 Circuit
B40: 1 | C40: Kirby - W | D40: Rosalina & Luma | M40: 1 | N40: Wolf | O40: Rosalina & Luma - W | V40: 1 | W40: Wii Fit Trainer - W | X40: Richter Belmont | AE40: 1 | AF40: Bowser Jr. | AG40: Wario - W | AN40: 1 | AO40: Sonic - W | AP40: Richter Belmont | AU40: 1 | AV40: Young Link | AW40: Toon Link - W | BB40: 1 | BC40: Robin - W | BD40: Ryu | BI40: 1 | BJ40: Toon Link | BK40: Corrin - W | BR40: 1 | BS40: Samus | BT40: Sonic - W | BX40: #1 Contender Human | BY40: 1 | BZ40: Simon Belmont - W | CA40: Diddy Kong | CI40: 1 | CP40: 1
C41: 2 | D41: 0 | N41: 0 | O41: 1 | W41: 2 | X41: 0 | AF41: 0 | AG41: 1 | AO41: 1 | AP41: 0 | AV41: 0 | AW41: 3 | BC41: 2 | BD41: 0 | BJ41: 0 | BK41: 1 | BS41: 0 | BT41: 2 | BZ41: 1 | CA41: 0
B42: 2 | C42: Pokemon Trainer | D42: Ice Climbers - W | M42: 2 | N42: Bowser Jr. - W | O42: Jigglypuff | V42: 2 | W42: Ken | X42: Sonic - W | AD42: #1 Contender Tag | AE42: 2 | AF42: Fox - W | AG42: Falco - W | AH42: Bayonetta | AI42: Inkling | AN42: 2 | AO42: Pokemon Trainer - W | AP42: Fox | AU42: 2 | AV42: Simon Belmont | AW42: Kirby - W | BA42: #14 & #13 | BB42: 2 | BC42: Pokemon Trainer | BD42: Ken - W | BH42: Spot in Hardcore | BI42: 2 | BJ42: Falco | BK42: Palutena - W | BQ42: #1 Contender Human | BR42: 2 | BS42: Bowser - W | BT42: Dark Samus | BY42: 2 | BZ42: Young Link - W | CA42: Rosalina & Luma | CI42: 2 | CP42: 2
C43: 0 | D43: 2 | N43: 1 | O43: 0 | W43: 0 | X43: 3 | AF43: 1 | AG43: 2 | AH43: 0 | AI43: 0 | AO43: 3 | AP43: 0 | AV43: 0 | AW43: 1 | BC43: 0 | BD43: 1 | BJ43: 0 | BK43: 0 | BS43: 2 | BT43: 0 | BZ43: 2 | CA43: 0
...

Sheet Season 7 Stats
A1: Brawl Fighters | B1: W | C1: L
A2: Toon Link | B2: =COUNTIF('Season 7'!A:AAO, CONCATENATE(TRIM(A2), " ","-"," ","W*")) -> 16 | C2: =SUM(COUNTIF('Season 7'!A:AAO, TRIM(A2)), COUNTIF('Season 7'!A:AAO, TRIM(A2) & " (Defending)"), COUNTIF('Season 7'!A:AAO, TRIM(A2) & " (PL)"), , COUNTIF('Season 7'!A:AAO, TRIM(A2) & " (PL) (Defending)")) -> 5
A3: Robin | B3: =COUNTIF('Season 7'!A:AAO, CONCATENATE(TRIM(A3), " ","-"," ","W*")) -> 14 | C3: =SUM(COUNTIF('Season 7'!A:AAO, TRIM(A3)), COUNTIF('Season 7'!A:AAO, TRIM(A3) & " (Defending)"), COUNTIF('Season 7'!A:AAO, TRIM(A3) & " (PL)"), , COUNTIF('Season 7'!A:AAO, TRIM(A3) & " (PL) (Defending)")) -> 6
A4: Kirby | B4: =COUNTIF('Season 7'!A:AAO, CONCATENATE(TRIM(A4), " ","-"," ","W*")) -> 14 | C4: =SUM(COUNTIF('Season 7'!A:AAO, TRIM(A4)), COUNTIF('Season 7'!A:AAO, TRIM(A4) & " (Defending)"), COUNTIF('Season 7'!A:AAO, TRIM(A4) & " (PL)"), , COUNTIF('Season 7'!A:AAO, TRIM(A4) & " (PL) (Defending)")) -> 6
A5: Marth | B5: =COUNTIF('Season 7'!A:AAO, CONCATENATE(TRIM(A5), " ","-"," ","W*")) -> 13 | C5: =SUM(COUNTIF('Season 7'!A:AAO, TRIM(A5)), COUNTIF('Season 7'!A:AAO, TRIM(A5) & " (Defending)"), COUNTIF('Season 7'!A:AAO, TRIM(A5) & " (PL)"), , COUNTIF('Season 7'!A:AAO, TRIM(A5) & " (PL) (Defending)")) -> 7
A6: Samus | B6: =COUNTIF('Season 7'!A:AAO, CONCATENATE(TRIM(A6), " ","-"," ","W*")) -> 13 | C6: =SUM(COUNTIF('Season 7'!A:AAO, TRIM(A6)), COUNTIF('Season 7'!A:AAO, TRIM(A6) & " (Defending)"), COUNTIF('Season 7'!A:AAO, TRIM(A6) & " (PL)"), , COUNTIF('Season 7'!A:AAO, TRIM(A6) & " (PL) (Defending)")) -> 7
A7: Luigi | B7: =COUNTIF('Season 7'!A:AAO, CONCATENATE(TRIM(A7), " ","-"," ","W*")) -> 12 | C7: =SUM(COUNTIF('Season 7'!A:AAO, TRIM(A7)), COUNTIF('Season 7'!A:AAO, TRIM(A7) & " (Defending)"), COUNTIF('Season 7'!A:AAO, TRIM(A7) & " (PL)"), , COUNTIF('Season 7'!A:AAO, TRIM(A7) & " (PL) (Defending)")) -> 10
A8: Dr. Mario | B8: =COUNTIF('Season 7'!A:AAO, CONCATENATE(TRIM(A8), " ","-"," ","W*")) -> 12 | C8: =SUM(COUNTIF('Season 7'!A:AAO, TRIM(A8)), COUNTIF('Season 7'!A:AAO, TRIM(A8) & " (Defending)"), COUNTIF('Season 7'!A:AAO, TRIM(A8) & " (PL)"), , COUNTIF('Season 7'!A:AAO, TRIM(A8) & " (PL) (Defending)")) -> 9
A9: Bowser | B9: =COUNTIF('Season 7'!A:AAO, CONCATENATE(TRIM(A9), " ","-"," ","W*")) -> 13 | C9: =SUM(COUNTIF('Season 7'!A:AAO, TRIM(A9)), COUNTIF('Season 7'!A:AAO, TRIM(A9) & " (Defending)"), COUNTIF('Season 7'!A:AAO, TRIM(A9) & " (PL)"), , COUNTIF('Season 7'!A:AAO, TRIM(A9) & " (PL) (Defending)")) -> 13
A10: Dark Samus | B10: =COUNTIF('Season 7'!A:AAO, CONCATENATE(TRIM(A10), " ","-"," ","W*")) -> 12 | C10: =SUM(COUNTIF('Season 7'!A:AAO, TRIM(A10)), COUNTIF('Season 7'!A:AAO, TRIM(A10) & " (Defending)"), COUNTIF('Season 7'!A:AAO, TRIM(A10) & " (PL)"), , COUNTIF('Season 7'!A:AAO, TRIM(A10) & " (PL) (Defending)")) -> 9
A11: Wario | B11: =COUNTIF('Season 7'!A:AAO, CONCATENATE(TRIM(A11), " ","-"," ","W*")) -> 12 | C11: =SUM(COUNTIF('Season 7'!A:AAO, TRIM(A11)), COUNTIF('Season 7'!A:AAO, TRIM(A11) & " (Defending)"), COUNTIF('Season 7'!A:AAO, TRIM(A11) & " (PL)"), , COUNTIF('Season 7'!A:AAO, TRIM(A11) & " (PL) (Defending)")) -> 10
A12: Palutena | B12: =COUNTIF('Season 7'!A:AAO, CONCATENATE(TRIM(A12), " ","-"," ","W*")) -> 11 | C12: =SUM(COUNTIF('Season 7'!A:AAO, TRIM(A12)), COUNTIF('Season 7'!A:AAO, TRIM(A12) & " (Defending)"), COUNTIF('Season 7'!A:AAO, TRIM(A12) & " (PL)"), , COUNTIF('Season 7'!A:AAO, TRIM(A12) & " (PL) (Defending)")) -> 11
A13: Sonic | B13: =COUNTIF('Season 7'!A:AAO, CONCATENATE(TRIM(A13), " ","-"," ","W*")) -> 11 | C13: =SUM(COUNTIF('Season 7'!A:AAO, TRIM(A13)), COUNTIF('Season 7'!A:AAO, TRIM(A13) & " (Defending)"), COUNTIF('Season 7'!A:AAO, TRIM(A13) & " (PL)"), , COUNTIF('Season 7'!A:AAO, TRIM(A13) & " (PL) (Defending)")) -> 11
... A26: Pichu | B26: =COUNTIF('Season 7'!A:AAO, CONCATENATE(TRIM(A26), " ","-"," ","W*")) -> 0 | C26: =SUM(COUNTIF('Season 7'!A:AAO, TRIM(A26)), COUNTIF('Season 7'!A:AAO, TRIM(A26) & " (Defending)"), COUNTIF('Season 7'!A:AAO, TRIM(A26) & " (PL)"), , COUNTIF('Season 7'!A:AAO, TRIM(A26) & " (PL) (Defending)")) -> 9
A28: Melee Fighters | B28: W | C28: L
A29: Ganondorf | B29: =COUNTIF('Season 7'!A:AAO, CONCATENATE(TRIM(A29), " ","-"," ","W*")) -> 21 | C29: =SUM(COUNTIF('Season 7'!A:AAO, TRIM(A29)), COUNTIF('Season 7'!A:AAO, TRIM(A29) & " (Defending)"), , COUNTIF('Season 7'!A:AAO, TRIM(A29) & " (PL)"), COUNTIF('Season 7'!A:AAO, TRIM(A29) & " (PL) (Defending)")) -> 4
A30: Lucas | B30: =COUNTIF('Season 7'!A:AAO, CONCATENATE(TRIM(A30), " ","-"," ","W*")) -> 18 | C30: =SUM(COUNTIF('Season 7'!A:AAO, TRIM(A30)), COUNTIF('Season 7'!A:AAO, TRIM(A30) & " (Defending)"), , COUNTIF('Season 7'!A:AAO, TRIM(A30) & " (PL)"), COUNTIF('Season 7'!A:AAO, TRIM(A30) & " (PL) (Defending)")) -> 7
A31: Incineroar | B31: =COUNTIF('Season 7'!A:AAO, CONCATENATE(TRIM(A31), " ","-"," ","W*")) -> 16 | C31: =SUM(COUNTIF('Season 7'!A:AAO, TRIM(A31)), COUNTIF('Season 7'!A:AAO, TRIM(A31) & " (Defending)"), , COUNTIF('Season 7'!A:AAO, TRIM(A31) & " (PL)"), COUNTIF('Season 7'!A:AAO, TRIM(A31) & " (PL) (Defending)")) -> 2
A32: Ness | B32: =COUNTIF('Season 7'!A:AAO, CONCATENATE(TRIM(A32), " ","-"," ","W*")) -> 15 | C32: =SUM(COUNTIF('Season 7'!A:AAO, TRIM(A32)), COUNTIF('Season 7'!A:AAO, TRIM(A32) & " (Defending)"), , COUNTIF('Season 7'!A:AAO, TRIM(A32) & " (PL)"), COUNTIF('Season 7'!A:AAO, TRIM(A32) & " (PL) (Defending)")) -> 10
A33: Ridley | B33: =COUNTIF('Season 7'!A:AAO, CONCATENATE(TRIM(A33), " ","-"," ","W*")) -> 14 | C33: =SUM(COUNTIF('Season 7'!A:AAO, TRIM(A33)), COUNTIF('Season 7'!A:AAO, TRIM(A33) & " (Defending)"), , COUNTIF('Season 7'!A:AAO, TRIM(A33) & " (PL)"), COUNTIF('Season 7'!A:AAO, TRIM(A33) & " (PL) (Defending)")) -> 6
A34: Dark Pit | B34: =COUNTIF('Season 7'!A:AAO, CONCATENATE(TRIM(A34), " ","-"," ","W*")) -> 12 | C34: =SUM(COUNTIF('Season 7'!A:AAO, TRIM(A34)), COUNTIF('Season 7'!A:AAO, TRIM(A34) & " (Defending)"), , COUNTIF('Season 7'!A:AAO, TRIM(A34) & " (PL)"), COUNTIF('Season 7'!A:AAO, TRIM(A34) & " (PL) (Defending)")) -> 11
A35: Link | B35: =COUNTIF('Season 7'!A:AAO, CONCATENATE(TRIM(A35), " ","-"," ","W*")) -> 10 | C35: =SUM(COUNTIF('Season 7'!A:AAO, TRIM(A35)), COUNTIF('Season 7'!A:AAO, TRIM(A35) & " (Defending)"), , COUNTIF('Season 7'!A:AAO, TRIM(A35) & " (PL)"), COUNTIF('Season 7'!A:AAO, TRIM(A35) & " (PL) (Defending)")) -> 9
A36: Cloud | B36: =COUNTIF('Season 7'!A:AAO, CONCATENATE(TRIM(A36), " ","-"," ","W*")) -> 10 | C36: =SUM(COUNTIF('Season 7'!A:AAO, TRIM(A36)), COUNTIF('Season 7'!A:AAO, TRIM(A36) & " (Defending)"), , COUNTIF('Season 7'!A:AAO, TRIM(A36) & " (PL)"), COUNTIF('Season 7'!A:AAO, TRIM(A36) & " (PL) (Defending)")) -> 7
A37: Mewtwo | B37: =COUNTIF('Season 7'!A:AAO, CONCATENATE(TRIM(A37), " ","-"," ","W*")) -> 10 | C37: =SUM(COUNTIF('Season 7'!A:AAO, TRIM(A37)), COUNTIF('Season 7'!A:AAO, TRIM(A37) & " (Defending)"), , COUNTIF('Season 7'!A:AAO, TRIM(A37) & " (PL)"), COUNTIF('Season 7'!A:AAO, TRIM(A37) & " (PL) (Defending)")) -> 8
A38: Yoshi | B38: =COUNTIF('Season 7'!A:AAO, CONCATENATE(TRIM(A38), " ","-"," ","W*")) -> 9 | C38: =SUM(COUNTIF('Season 7'!A:AAO, TRIM(A38)), COUNTIF('Season 7'!A:AAO, TRIM(A38) & " (Defending)"), , COUNTIF('Season 7'!A:AAO, TRIM(A38) & " (PL)"), COUNTIF('Season 7'!A:AAO, TRIM(A38) & " (PL) (Defending)")) -> 5
A39: Lucina | B39: =COUNTIF('Season 7'!A:AAO, CONCATENATE(TRIM(A39), " ","-"," ","W*")) -> 9 | C39: =SUM(COUNTIF('Season 7'!A:AAO, TRIM(A39)), COUNTIF('Season 7'!A:AAO, TRIM(A39) & " (Defending)"), , COUNTIF('Season 7'!A:AAO, TRIM(A39) & " (PL)"), COUNTIF('Season 7'!A:AAO, TRIM(A39) & " (PL) (Defending)")) -> 12
A40: Wolf | B40: =COUNTIF('Season 7'!A:AAO, CONCATENATE(TRIM(A40), " ","-"," ","W*")) -> 9 | C40: =SUM(COUNTIF('Season 7'!A:AAO, TRIM(A40)), COUNTIF('Season 7'!A:AAO, TRIM(A40) & " (Defending)"), , COUNTIF('Season 7'!A:AAO, TRIM(A40) & " (PL)"), COUNTIF('Season 7'!A:AAO, TRIM(A40) & " (PL) (Defending)")) -> 9
... A52: Bayonetta | B52: =COUNTIF('Season 7'!A:AAO, CONCATENATE(TRIM(A52), " ","-"," ","W*")) -> 0 | C52: =SUM(COUNTIF('Season 7'!A:AAO, TRIM(A52)), COUNTIF('Season 7'!A:AAO, TRIM(A52) & " (Defending)"), , COUNTIF('Season 7'!A:AAO, TRIM(A52) & " (PL)"), COUNTIF('Season 7'!A:AAO, TRIM(A52) & " (PL) (Defending)")) -> 13
A54: Ultimate Fighters | B54: W | C54: L
A55: Chrom | B55: =COUNTIF('Season 7'!A:AAO, CONCATENATE(TRIM(A55), " ","-"," ","W*")) -> 16 | C55: =SUM(COUNTIF('Season 7'!A:AAO, TRIM(A55)), COUNTIF('Season 7'!A:AAO, TRIM(A55) & " (Defending)"), COUNTIF('Season 7'!A:AAO, TRIM(A55) & " (PL)"), COUNTIF('Season 7'!A:AAO, TRIM(A55) & " (PL) (Defending)")) -> 6
A56: King Dedede | B56: =COUNTIF('Season 7'!A:AAO, CONCATENATE(TRIM(A56), " ","-"," ","W*")) -> 14 | C56: =SUM(COUNTIF('Season 7'!A:AAO, TRIM(A56)), COUNTIF('Season 7'!A:AAO, TRIM(A56) & " (Defending)"), COUNTIF('Season 7'!A:AAO, TRIM(A56) & " (PL)"), COUNTIF('Season 7'!A:AAO, TRIM(A56) & " (PL) (Defending)")) -> 9
A57: ROB | B57: =COUNTIF('Season 7'!A:AAO, CONCATENATE(TRIM(A57), " ","-"," ","W*")) -> 12 | C57: =SUM(COUNTIF('Season 7'!A:AAO, TRIM(A57)), COUNTIF('Season 7'!A:AAO, TRIM(A57) & " (Defending)"), COUNTIF('Season 7'!A:AAO, TRIM(A57) & " (PL)"), COUNTIF('Season 7'!A:AAO, TRIM(A57) & " (PL) (Defending)")) -> 9
A58: Mario | B58: =COUNTIF('Season 7'!A:AAO, CONCATENATE(TRIM(A58), " ","-"," ","W*")) -> 12 | C58: =SUM(COUNTIF('Season 7'!A:AAO, TRIM(A58)), COUNTIF('Season 7'!A:AAO, TRIM(A58) & " (Defending)"), COUNTIF('Season 7'!A:AAO, TRIM(A58) & " (PL)"), COUNTIF('Season 7'!A:AAO, TRIM(A58) & " (PL) (Defending)")) -> 6
A59: Shulk | B59: =COUNTIF('Season 7'!A:AAO, CONCATENATE(TRIM(A59), " ","-"," ","W*")) -> 13 | C59: =SUM(COUNTIF('Season 7'!A:AAO, TRIM(A59)), COUNTIF('Season 7'!A:AAO, TRIM(A59) & " (Defending)"), COUNTIF('Season 7'!A:AAO, TRIM(A59) & " (PL)"), COUNTIF('Season 7'!A:AAO, TRIM(A59) & " (PL) (Defending)")) -> 5
A60: Ike | B60: =COUNTIF('Season 7'!A:AAO, CONCATENATE(TRIM(A60), " ","-"," ","W*")) -> 13 | C60: =SUM(COUNTIF('Season 7'!A:AAO, TRIM(A60)), COUNTIF('Season 7'!A:AAO, TRIM(A60) & " (Defending)"), COUNTIF('Season 7'!A:AAO, TRIM(A60) & " (PL)"), COUNTIF('Season 7'!A:AAO, TRIM(A60) & " (PL) (Defending)")) -> 8
A61: Mega Man | B61: =COUNTIF('Season 7'!A:AAO, CONCATENATE(TRIM(A61), " ","-"," ","W*")) -> 12 | C61: =SUM(COUNTIF('Season 7'!A:AAO, TRIM(A61)), COUNTIF('Season 7'!A:AAO, TRIM(A61) & " (Defending)"), COUNTIF('Season 7'!A:AAO, TRIM(A61) & " (PL)"), COUNTIF('Season 7'!A:AAO, TRIM(A61) & " (PL) (Defending)")) -> 7
A62: Roy | B62: =COUNTIF('Season 7'!A:AAO, CONCATENATE(TRIM(A62), " ","-"," ","W*")) -> 10 | C62: =SUM(COUNTIF('Season 7'!A:AAO, TRIM(A62)), COUNTIF('Season 7'!A:AAO, TRIM(A62) & " (Defending)"), COUNTIF('Season 7'!A:AAO, TRIM(A62) & " (PL)"), COUNTIF('Season 7'!A:AAO, TRIM(A62) & " (PL) (Defending)")) -> 7
A63: Joker | B63: =COUNTIF('Season 7'!A:AAO, CONCATENATE(TRIM(A63), " ","-"," ","W*")) -> 10 | C63: =SUM(COUNTIF('Season 7'!A:AAO, TRIM(A63)), COUNTIF('Season 7'!A:AAO, TRIM(A63) & " (Defending)"), COUNTIF('Season 7'!A:AAO, TRIM(A63) & " (PL)"), COUNTIF('Season 7'!A:AAO, TRIM(A63) & " (PL) (Defending)")) -> 10
A64: Pikachu | B64: =COUNTIF('Season 7'!A:AAO, CONCATENATE(TRIM(A64), " ","-"," ","W*")) -> 10 | C64: =SUM(COUNTIF('Season 7'!A:AAO, TRIM(A64)), COUNTIF('Season 7'!A:AAO, TRIM(A64) & " (Defending)"), COUNTIF('Season 7'!A:AAO, TRIM(A64) & " (PL)"), COUNTIF('Season 7'!A:AAO, TRIM(A64) & " (PL) (Defending)")) -> 9
A65: Pac-Man | B65: =COUNTIF('Season 7'!A:AAO, CONCATENATE(TRIM(A65), " ","-"," ","W*")) -> 9 | C65: =SUM(COUNTIF('Season 7'!A:AAO, TRIM(A65)), COUNTIF('Season 7'!A:AAO, TRIM(A65) & " (Defending)"), COUNTIF('Season 7'!A:AAO, TRIM(A65) & " (PL)"), COUNTIF('Season 7'!A:AAO, TRIM(A65) & " (PL) (Defending)")) -> 9
...

Sheet Season 7 Awards
B1: Superstar of the Year | C1: W | D1: L | E1: Description
A2: 1
A3: 2
A4: 3
A5: 4
A6: 5
B8: Brawl Superstar of the Year | C8: W | D8: L | E8: Description
A9: 1
A10: 2
A11: 3
B13: Melee Superstar of the Year | C13: W | D13: L | E13: Description
A14: 1
A15: 2
A16: 3
B18: Ultimate Superstar of the Year | C18: W | D18: L | E18: Description
A19: 1
A20: 2
A21: 3
B23: Tag Team of the Year
A24: 1
A25: 2
B27: Most Improved (Breakout) | C27: W | D27: L
A28: 1
A29: 2
A30: 3
A31: 4
A32: 5
B34: Most Disappointing | C34: W | D34: L
A35: 1
A36: 2
A37: 3
A38: 4
A39: 5
B41: Match of the Year
A42: 1
A43: 2
A44: 3
A45: 4
A46: 5

Sheet Season 7 Draft
A1: Order (Snake Draft)
A2: Brawl
A3: Ultimate
A4: Melee
L5: Brawl | M5: Melee | N5: Ultimate
B7: Protected Fighters: | C7: Kirby | D7: Brawl Champion | E7: Protected Fighters: | F7: Ganondorf | G7: Melee Champion | H7: Protected Fighters: | I7: Mario | J7: Ultimate Champion
C8: Marth | D8: Human Champion | F8: Lucina | G8: Animal Champion | I8: Dr. Mario | J8: Monster Champion
C9: Robin | D9: Hardcore Champion | F9: Incineroar | G9: Special Champion | I9: Mega Man | J9: Chaos Champion
C10: Samus | D10: MITB Brawl | F10: Yoshi | G10: MITB Melee | I10: Shulk | J10: MITB Ultimate
A11: Round 1 Protected | C11: Toon Link | F11: Cloud | I11: Pikachu
A12: Round 1 Draft | C12: Luigi | F12: Ness | I12: ROB
A13: Round 2 Protected | C13: Wario | F13: Dark Pit | I13: Ike
A14: Round 2 Draft | C14: Bowser | F14: Link | I14: Joker
A15: Round 3 Protected | C15: Sonic | F15: Lucas | I15: King Dedede
A16: Round 3 Protected | C16: Simon Belmont | F16: DK | I16: Roy
A17: Round 3 Draft | C17: Diddy Kong | F17: Mr. Game & Watch | I17: Pit
A18: Round 4 Protected | C18: Ken | F18: King K. Rool | I18: Captain Falcon
A19: Round 4 Protected | C19: Palutena | F19: Ridley | I19: Chrom
A20: Round 4 Draft | C20: Young Link | F20: Wolf | I20: Meta Knight
A21: Round 5 Protected | C21: Falco | F21: Mewtwo | I21: Snake
A22: Round 5 Draft | C22: Dark Samus | F22: Greninja | I22: Fox
... A30: Round 8 Draft | C30: Pichu | F30: Daisy | I30: Wii Fit Trainer

Sheet Season 6
A1: Month 1 | B1: Royal Rumble | L1: Month 2 | M1: Pokeslam | U1: Month 3 | V1: Brawlmania | AD1: Month 4 | AE1: Money in the Bank | AM1: Month 5 | AN1: Ignition | AT1: Month 6 | AU1: Summer Slam | BA1: Month 7 | BB1: Final Destination Tournament | BH1: Month 8 | BI1: The Great Race | BQ1: Month 9 | BR1: King of the Hill | BX1: Month 10 | BY1: Smash Series | CH1: Month 11 | CI1: Championship Cruise | CO1: Month 12 | CP1: Championship Scramble
B3: Brawl | C3: Battlefield | M3: Brawl | N3: Jungle Japes | V3: Brawl | W3: Pokemon Stadium 2 | AE3: Brawl | AF3: Bridge of Eldin | AN3: Brawl | AO3: New Pork City (Battlefield) | AU3: Brawl | AV3: Golden Plains | BB3: Brawl | BC3: Reset Bomb Forest | BF3: Trade: Diddy Kong (to Melee) for Wario (to Brawl) | BI3: Brawl | BJ3: Mario Circuit | BR3: Brawl | BS3: Wii Fit Studio | BY3: Brawl | BZ3: Super Mario Maker | CI3: Brawl | CJ3: Big Blue | CP3: Brawl | CQ3: Umbra Clock Tower
B4: 1 | C4: Richter Belmont - W | D4: Dr. Mario | M4: 1 | N4: Ken | O4: Bowser Jr. - W | V4: 1 | W4: Diddy Kong | X4: Dr. Mario - W | AD4: Spot in MITB | AE4: 1 | AF4: Wii Fit Trainer | AG4: Sonic - W | AN4: 1 | AO4: Young Link - W | AP4: Rosalina & Luma | AU4: 1 | AV4: Ice Climbers - W | AW4: Jigglypuff | AX4: Daisy | BB4: 1 | BC4: Wario - W | BD4: Ryu | BI4: 1 | BJ4: Robin - W | BK4: Ice Climbers | BR4: 1 | BS4: ROB - W | BT4: Ken | BY4: 1 | BZ4: Samus - W | CA4: Palutena | CI4: 1 | CJ4: Ryu | CK4: Kirby - W | CP4: 1 | CQ4: Pokemon Trainer - W | CR4: Daisy
C5: 2 | D5: 0 | N5: 0 | O5: 1 | W5: 0 | X5: 1 | AF5: 0 | AG5: 1 | AO5: 3 | AP5: 0 | AV5: 1 | AW5: 0 | AX5: 0 | BC5: 2 | BD5: 0 | BJ5: 2 | BK5: 0 | BS5: 3 | BT5: 0 | BZ5: 2 | CA5: 0 | CJ5: 0 | CK5: 3 | CQ5: 1 | CR5: 0
B6: 2 | C6: Bayonetta | D6: Ryu - W | M6: 2 | N6: Dr. Mario - W | O6: Little Mac | V6: 2 | W6: Wii Fit Trainer | X6: Simon Belmont - W | AD6: Battle of the winless | AE6: 2 | AF6: Bayonetta - W | AG6: Ken | AN6: 2 | AO6: Ryu | AP6: Ridley - W | AU6: 2 | AV6: Falco | AW6: Ryu - W | BB6: 2 | BC6: Link - W | BD6: Samus | BI6: 2 | BJ6: Kirby - W | BK6: Fox | BR6: 2 | BS6: Ice Climbers | BT6: Sonic - W | BY6: 2 | BZ6: Sonic - W | CA6: Rosalina & Luma | CI6: 2 | CJ6: Ken | CK6: Pokemon Trainer - W | CP6: 2 | CQ6: Wolf - W | CR6: Ken
C7: 0 | D7: 1 | N7: 2 | O7: 0 | W7: 0 | X7: 3 | AF7: 1 | AG7: 0 | AO7: 0 | AP7: 3 | AV7: 0 | AW7: 1 | BC7: 1 | BD7: 0 | BJ7: 2 | BK7: 0 | BS7: 0 | BT7: 1 | BZ7: 2 | CA7: 0 | CJ7: 0 | CK7: 3 | CQ7: 2 | CR7: 0
B8: 3 | C8: Young Link | D8: Toon Link - W | L8: Pokeball Spot | M8: 3 | N8: Diddy Kong | O8: Robin - W | V8: 3 | W8: Toon Link - W | X8: Bowser Jr. | AD8: Spot in MITB | AE8: 3 | AF8: Wolf | AG8: Dr. Mario - W | AM8: Beat the clock for Brawl spot | AN8: 3 | AO8: Diddy Kong - W | AP8: Wolf | AU8: 3 | AV8: Robin | AW8: Palutena - W | BB8: 3 | BC8: Marth - W | BD8: Kirby | BH8: Spot in Human | BI8: 3 | BJ8: Rosalina & Luma | BK8: Wolf - W | BR8: 3 | BS8: Robin - W | BT8: Wii Fit Trainer | BY8: 3 | BZ8: Pokemon Trainer - W | CA8: Ice Climbers | CI8: 3 | CJ8: Samus - W | CK8: Palutena | CP8: 3 | CQ8: Rosalina & Luma | CR8: Fox - W
C9: 0 | D9: 1 | N9: 0 | O9: 2 | W9: 1 | X9: 0 | AF9: 0 | AG9: 2 | AM9: 0.13194444 | AO9: 1 | AP9: 0 | AV9: 0 | AW9: 1 | BC9: 1 | BD9: 0 | BJ9: 0 | BK9: 3 | BS9: 2 | BT9: 0 | BZ9: 1 | CA9: 0 | CJ9: 1 | CK9: 0 | CQ9: 0 | CR9: 1
B10: 4 | C10: Ridley - W | D10: Wii Fit Trainer | M10: 4 | N10: Pokemon Trainer - W | O10: Sonic | V10: 4 | W10: Ryu | X10: ROB - W | AE10: 4 | AF10: Simon Belmont - W | AG10: Little Mac | AM10: Beat the Clock for Brawl spot | AN10: 4 | AO10: ROB - W | AP10: Roy | AU10: 4 | AV10: Link | AW10: Toon Link - W | BA10: #16 seed | BB10: 4 | BC10: Ken | BD10: Pokemon Trainer | BE10: Daisy - W | BF10: Bowser Jr. | BI10: 4 | BJ10: Wario - W | BK10: Toon Link | BQ10: Winner put in #1 contender for Brawl next week | BR10: 4 | BS10: Marth | BT10: Toon Link - W | BY10: 4 | BZ10: Wolf - W | CA10: Ken | CI10: 4 | CJ10: Wolf | CK10: Link - W | CP10: 4 | CQ10: Richter Belmont - W | CR10: Ryu
C11: 3 | D11: 0 | N11: 2 | O11: 0 | W11: 0 | X11: 3 | AF11: 2 | AG11: 0 | AM11: 0.13819444 | AO11: 2 | AP11: 0 | AV11: 0 | AW11: 1 | BC11: 0 | BD11: 0 | BE11: 1 | BF11: 0 | BJ11: 2 | BK11: 0 | BS11: 0 | BT11: 1 | BZ11: 3 | CA11: 0 | CJ11: 0 | CK11: 1 | CQ11: 3 | CR11: 0
A12: Spot in Royal Rumble | B12: 5 | C12: Sonic | D12: ROB - W | L12: #1 Contender Hardcore | M12: 5 | N12: Richter Belmont - W | O12: Ryu | P12: Dark Samus | U12: #1 Contender Human | V12: 5 | W12: Corrin - W | X12: Robin | AD12: #1 Contender Hardcore | AE12: 5 | AF12: Roy - W | AG12: Robin | AM12: Beat the clock for Brawl spot | AN12: 5 | AO12: Simon Belmont - W | AP12: Richter Belmont - W | AT12: #1 Contender Human | AU12: 5 | AV12: Diddy Kong - W | AW12: Wolf | BA12: #15 seed | BB12: 5 | BC12: Falco | BD12: Ice Climbers | BE12: Wii Fit Trainer | BF12: Robin - W | BH12: Spot in Hardcore | BI12: 5 | BJ12: Richter Belmont | BK12: Sonic - W | BQ12: #1 Contender Hardcore | BR12: 5 | BS12: Link - W | BT12: Samus | BX12: #1 Contender Human | BY12: 5 | BZ12: Richter Belmont - W | CA12: Ryu | CH12: #1 Contender Hardcore | CI12: 5 | CJ12: Rosalina & Luma - W | CK12: Fox | CO12: Spot in Brawl | CP12: 5 | CQ12: Marth | CR12: Link - W
N13: 4 | O13: -3 | P13: -1 | W13: 1 | X13: 0 | AF13: 2 | AG13: -2 | AM13: 0.090277778 | AO13: 0 | AP13: 2 | AV13: 2 | AW13: 0 | BC13: 0 | BD13: 0 | BE13: 0 | BF13: 1 | BH13: KO's own assist trophy for win | BJ13: 0 | BK13: 1 | BS13: 6 | BT13: -6 | BZ13: 3 | CA13: 0 | CJ13: 0 | CK13: 0 | CQ13: 0 | CR13: 1
B15: Melee | C15: Peach's Castle | M15: Melee | N15: Great Bay | V15: Melee | W15: Onett | AE15: Melee | AF15: Norfair | AN15: Melee | AO15: Skyworld | AU15: Melee | AV15: Paper Mario | BB15: Melee | BC15: Tortimer Island | BI15: Melee | BJ15: Skyloft | BR15: Melee | BS15: Gaur Plain (Battlefield) | BY15: Melee | BZ15: Hanenbow | CI15: Melee | CJ15: Fountain of Dreams | CP15: Melee | CQ15: Midgar
B16: 1 | C16: Lucina - W | D16: Palutena | M16: 1 | N16: Lucario - W | O16: Duck Hunt | V16: 1 | W16: Isabelle | X16: DK - W | AE16: 1 | AF16: Pit - W | AG16: Isabelle | AN16: 1 | AO16: Luigi - W | AP16: Villager | AU16: 1 | AV16: Corrin - W | AW16: Lucina | BB16: 1 | BC16: Meta Knight | BD16: Diddy Kong - W | BI16: 1 | BJ16: Ridley | BK16: Corrin - W | BR16: 1 | BS16: Incineroar | BT16: Lucina - W | BY16: 1 | BZ16: Meta Knight - W | CA16: Zelda | CI16: 1 | CJ16: DK - W | CK16: Dark Samus | CP16: 1 | CQ16: Ridley - W | CR16: Mewtwo
C17: 3 | D17: 0 | N17: 3 | O17: 0 | W17: 0 | X17: 2 | AF17: 2 | AG17: 0 | AO17: 1 | AP17: 0 | AV17: 1 | AW17: 0 | BC17: 0 | BD17: 2 | BJ17: 0 | BK17: 1 | BS17: 0 | BT17: 2 | BZ17: 1 | CA17: 0 | CJ17: 2 | CK17: 0 | CQ17: 1 | CR17: 0
B18: 2 | C18: King K. Rool - W | D18: DK | M18: 2 | N18: Luigi - W | O18: Pac-Man | V18: 2 | W18: Fox | X18: Inkling - W | AE18: 2 | AF18: Palutena - W | AG18: Olimar | AN18: 2 | AO18: Ganondorf - W | AP18: Zelda | AU18: 2 | AV18: Mewtwo | AW18: Dark Samus - W | BB18: 2 | BC18: Dark Pit - W | BD18: Lucina | BI18: 2 | BJ18: Mewtwo | BK18: Zelda - W | BR18: 2 | BS18: Ridley - W | BT18: Mewtwo | BY18: 2 | BZ18: Ganondorf - W | CA18: Lucas | CI18: 2 | CJ18: Cloud | CK18: Ridley - W | CP18: 2 | CQ18: Incineroar - W | CR18: Corrin
C19: 2 | D19: 0 | N19: 1 | O19: 0 | W19: 0 | X19: 2 | AF19: 2 | AG19: 0 | AO19: 2 | AP19: 0 | AV19: 0 | AW19: 2 | BC19: 2 | BD19: 0 | BJ19: 0 | BK19: 2 | BS19: 2 | BT19: 0 | BZ19: 2 | CA19: 0 | CJ19: 0 | CK19: 1 | CQ19: 1 | CR19: 0
B20: 3 | C20: Inkling - W | D20: Pac-Man | L20: Pokeball Spot | M20: 3 | N20: Villager | O20: Lucina - W | V20: 3 | W20: Zelda - W | X20: Meta Knight | AD20: Spot in MITB | AE20: 3 | AF20: Pac-Man | AG20: Lucario - W | AN20: 3 | AO20: Lucario - W | AP20: Lucina | AU20: 3 | AV20: Incineroar - W | AW20: Olimar | BB20: 3 | BC20: Cloud - W | BD20: Dark Samus | BI20: 3 | BJ20: Pit | BK20: Diddy Kong - W | BR20: 3 | BS20: Cloud - W | BT20: Pit | BY20: 3 | BZ20: Incineroar - W | CA20: Corrin | CI20: 3 | CJ20: Lucas - W | CK20: Isabelle | CP20: 3 | CQ20: DK - W | CR20: Pit
C21: 1 | D21: 0 | N21: 0 | O21: 1 | W21: 2 | X21: 0 | AF21: 0 | AG21: 2 | AO21: 2 | AP21: 0 | AV21: 1 | AW21: 0 | BC21: 2 | BD21: 0 | BJ21: 0 | BK21: 3 | BS21: 3 | BT21: 0 | BZ21: 1 | CA21: 0 | CJ21: 2 | CK21: 0 | CQ21: 1 | CR21: 0
